<?xml version="1.0"?>

<robot name="justina_base" xmlns:xacro="http://www.ros.org/wiki/xacro">

    <!-- Robot Parameters -->
    <xacro:property name="PI" value="3.14159265"/>
    <xacro:property name="body_length" value="0.45"/>
    <xacro:property name="body_width" value="0.35"/>
    <xacro:property name="body_height" value="0.1"/>
    <xacro:property name="body_density" value="7850.0"/> <!-- Steel -->
    <xacro:property name="body_mass" value="${body_density * body_length * body_height * body_width}"/>
    <xacro:property name="body_inertia_x" value="${1.0/12.0 * body_mass * (body_height*body_height + body_width*body_width)}"/>
    <xacro:property name="body_inertia_y" value="${1.0/12.0 * body_mass * (body_length*body_length + body_height*body_height)}"/>
    <xacro:property name="body_inertia_z" value="${1.0/12.0 * body_mass * (body_length*body_length + body_width*body_width)}"/>

    <xacro:property name="wheel_radius" value="0.07"/>
    <xacro:property name="wheel_width" value="0.04"/>
    <xacro:property name="wheel_separation" value="${body_width + wheel_width}"/>
    <xacro:property name="wheel_offset" value="${body_length/2 - wheel_radius}"/>
    <xacro:property name="wheel_offset_z" value="0.05"/>
    <xacro:property name="wheel_density" value="900"/> <!-- Ruber -->
    <xacro:property name="wheel_mass" value="${wheel_density * PI * wheel_radius * wheel_radius * wheel_width}"/>
    <xacro:property name="wheel_inertia_x" value="${1.0/12.0 * wheel_mass * (3*wheel_radius*wheel_radius + wheel_width*wheel_width)}"/>
    <xacro:property name="wheel_inertia_y" value="${1.0/12.0 * wheel_mass * (3*wheel_radius*wheel_radius + wheel_width*wheel_width)}"/>
    <xacro:property name="wheel_inertia_z" value="${1.0/2.0 * wheel_mass * wheel_radius * wheel_radius}"/>

    <xacro:property name="caster_radius" value="0.07"/>
    <xacro:property name="caster_offset" value="${body_length/2 - caster_radius}"/>
    <xacro:property name="caster_density" value="0.1"/>
    <xacro:property name="caster_mass" value="${caster_density * 4.0/3.0 * PI * caster_radius * caster_radius * caster_radius}"/>
    <xacro:property name="caster_inertia_x" value="${2.0/5.0 * caster_mass * caster_radius * caster_radius}"/>
    <xacro:property name="caster_inertia_y" value="${2.0/5.0 * caster_mass * caster_radius * caster_radius}"/>
    <xacro:property name="caster_inertia_z" value="${2.0/5.0 * caster_mass * caster_radius * caster_radius}"/>

    <xacro:property name="laser_radius" value="0.06"/>
    <xacro:property name="laser_height" value="0.05"/>
    <xacro:property name="laser_mass" value="0.2"/>
    <xacro:property name="laser_inertia_xx" value="${(1/12) * laser_mass * (3*laser_radius*laser_radius + laser_height*laser_height)}"/>
    <xacro:property name="laser_inertia_yy" value="${(1/12) * laser_mass * (3*laser_radius*laser_radius + laser_height*laser_height)}"/>
    <xacro:property name="laser_inertia_zz" value="${(1/2) * laser_mass * laser_radius*laser_radius}"/>
    

    <!-- Control Parameters -->    
    <xacro:property name="max_linear_acceleration" value="10"/>
    <xacro:arg name="namespace" default="" />
    <xacro:arg name="body_color" default="0.05 0.05 0.95 1.0" />
    <xacro:arg name="cmd_vel_topic" default="/cmd_vel" />
    <xacro:arg name="odom_topic"    default="/odom" />
    <xacro:arg name="odom_frame"    default="odom" />
    <xacro:arg name="base_frame"    default="base_link" />
    <!-- Links -->
    <link name="base_link"/>
    <!-- Body Link -->
    <link name="body_link">
        <visual>
            <origin xyz="0.0 0.0 0.0" rpy="0.0 0.0 0.0"/>
            <geometry>
                <box size="${body_length} ${body_width} ${body_height}"/>
            </geometry>
            <material name="body_material">
                <color rgba="$(arg body_color)"/>
            </material>
        </visual>
        <collision>
            <origin xyz="0.0 0.0 0.0" rpy="0.0 0.0 0.0"/>
            <geometry>
                <box size="${body_length} ${body_width} ${body_height}"/>
            </geometry>
        </collision>
        <inertial>
            <mass value="10"/>
            <inertia ixx="${body_inertia_x}" ixy="0.0" ixz="0.0" iyy="${body_inertia_y}" iyz="0" izz="${body_inertia_z}"/>
            <origin xyz="0 0 0" rpy="0 0 0"/>
        </inertial>
    </link>

    <!-- Left Wheel -->
    <link name="left_wheel_link">
        <visual>
            <origin xyz="0.0 0.0 0.0" rpy="1.570795 0.0 0.0"/>
            <geometry>
                <cylinder radius="${wheel_radius}" length="${wheel_width}"/>
            </geometry>
            <material name="wheel_material">
                <color rgba="0.0 0.0 0.0 1.0"/>
            </material>
        </visual>
        <collision>
            <origin xyz="0.0 0.0 0.0" rpy="1.570795 0.0 0.0"/>
            <geometry>
                <cylinder radius="${wheel_radius}" length="${wheel_width}"/>
            </geometry>
        </collision>
        <inertial>
            <mass value="2"/>
            <inertia ixx="${wheel_inertia_x}" ixy="0.0" ixz="0.0" iyy="${wheel_inertia_y}" iyz="0" izz="${wheel_inertia_z}"/>
            <origin xyz="0.0 0.0 0.0" rpy="1.570795 0.0 0.0"/>
        </inertial>
    </link>

    <!-- Right Wheel -->
    <link name="right_wheel_link">
        <visual>
            <origin xyz="0.0 0.0 0.0" rpy="1.570795 0.0 0.0"/>
            <geometry>
                <cylinder radius="${wheel_radius}" length="${wheel_width}"/>
            </geometry>
            <material name="wheel_material">
                <color rgba="0.0 0.0 0.0 1.0"/>
            </material>
        </visual>
        <collision>
            <origin xyz="0.0 0.0 0.0" rpy="1.570795 0.0 0.0"/>
            <geometry>
                <cylinder radius="${wheel_radius}" length="${wheel_width}"/>
            </geometry>
        </collision>
        <inertial>
            <mass value="2"/>
            <inertia ixx="${wheel_inertia_x}" ixy="0.0" ixz="0.0" iyy="${wheel_inertia_y}" iyz="0" izz="${wheel_inertia_z}"/>
            <origin xyz="0.0 0.0 0.0" rpy="1.570795 0.0 0.0"/>
        </inertial>
    </link>

    <!-- Caster Wheel -->
    <link name="caster_link">
        <visual>
            <origin xyz="0.0 0.0 0.0" rpy="0.0 0.0 0.0"/>
            <geometry>
                <sphere radius="${caster_radius}"/>
            </geometry>
            <material name="caster_material">
                <color rgba="0.0 0.0 0.0 1.0"/>
            </material>
        </visual>
        <collision>
            <origin xyz="0.0 0.0 0.0" rpy="0.0 0.0 0.0"/>
            <geometry>
                <sphere radius="${caster_radius}"/>
            </geometry>
        </collision>
        <inertial>
            <mass value="0.5"/>
            <inertia ixx="${caster_inertia_x}" ixy="0.0" ixz="0.0" iyy="${caster_inertia_y}" iyz="0" izz="${caster_inertia_z}"/>
            <origin xyz="0 0 0" rpy="0 0 0"/>
        </inertial>
    </link>

    <link name="laser_link">
      <visual>
         <origin xyz="0 0 0"/>
         <geometry>
            <cylinder length="${laser_height}" radius="${laser_radius}"/>
         </geometry>
         <material name="laser_material">
            <color rgba="0.07 0.07 0.07 1.0"/>
         </material>
      </visual>
      <collision>
         <origin xyz="0 0 0"/>
         <geometry>
            <cylinder length="${laser_height}" radius="${laser_radius}"/>
         </geometry>
      </collision>
      <inertial>
        <mass value="${laser_mass}"/>
        <inertia ixx="${laser_inertia_xx}" ixy="0.0" ixz="0.0" iyy="${laser_inertia_yy}" iyz="0" izz="${laser_inertia_zz}"/>
        <origin xyz="0 0 0" rpy="0 0 0"/>
      </inertial>
   </link>

   <!-- Joints -->
   <joint name="base_to_body" type="fixed">
     <origin xyz="0 0 ${body_height/2}" rpy="0 0 0"/>
     <parent link="base_link"/>
     <child link="body_link"/>
   </joint>

   <!-- Left Wheel Joint -->
   <joint name="left_wheel_joint" type="continuous">
     <origin xyz="${wheel_offset} ${wheel_separation/2} ${-wheel_radius/2 - wheel_offset_z}" rpy="0 0 0"/>
     <parent link="body_link"/>
     <child link="left_wheel_link"/>
     <axis xyz="0 1 0"/>
     <limit effort="100" velocity="10.0"/>
     <dynamics damping="0.1" friction="0.1"/>
   </joint>
   
   <!-- Right Wheel Joint -->
   <joint name="right_wheel_joint" type="continuous">
        <origin xyz="${wheel_offset} ${-wheel_separation/2} ${-wheel_radius/2 - wheel_offset_z}" rpy="0 0 0"/>
        <parent link="body_link"/>
        <child link="right_wheel_link"/>
        <axis xyz="0 1 0"/>
        <limit effort="100" velocity="10.0"/>
        <dynamics damping="0.1" friction="0.1"/>
    </joint>

    <!-- Caster Wheel Joint (fixed) -->
    <joint name="caster_joint" type="fixed">
        <origin xyz="${-caster_offset} 0 ${-caster_radius/2 - wheel_offset_z}" rpy="0 0 0"/>
        <parent link="body_link"/>
        <child link="caster_link"/>
    </joint>

    <!-- Body to laser joint -->
    <joint name="laser_joint" type="fixed">
      <origin xyz="${body_length/2 - laser_radius} 0.0 ${body_height/2+laser_height/2}" rpy="0 0 0"/>
      <parent link="body_link"/>
      <child link="laser_link"/>
    </joint>

    <!-- Gazebo Parameters -->
    <gazebo reference="body_link">
        <mu1>1.0</mu1>
        <mu2>1.0</mu2>
    </gazebo>

    <gazebo reference="right_wheel_link">
        <mu1>1.0</mu1>
        <mu2>1.0</mu2>
    </gazebo>

    <gazebo reference="left_wheel_link">
        <mu1>1.0</mu1>
        <mu2>1.0</mu2>
    </gazebo>

    <gazebo reference="caster_link">
        <mu1>0.000001</mu1>
        <mu2>0.000001</mu2>
    </gazebo>

    <gazebo reference="laser_link">
        <mu1>1.0</mu1>
        <mu2>1.0</mu2>
    </gazebo>

    <!-- Gazebo Plugins -->
    <gazebo>
      <plugin filename="gz-sim-diff-drive-system" name="gz::sim::systems::DiffDrive">
        <right_joint>right_wheel_joint</right_joint>
        <left_joint>left_wheel_joint</left_joint>
        <wheel_separation>${wheel_separation}</wheel_separation>
        <wheel_radius>${wheel_radius}</wheel_radius>
        <max_linear_acceleration>${max_linear_acceleration}</max_linear_acceleration>
        <odom_publish_frequency>100</odom_publish_frequency>
        <topic>$(arg cmd_vel_topic)</topic>
        <tf_topic>tf</tf_topic>
        <frame_id>$(arg odom_frame)</frame_id>
        <child_frame_id>$(arg base_frame)</child_frame_id>
        <odom_topic>$(arg odom_topic)</odom_topic>
      </plugin>
      
      <plugin filename="gz-sim-joint-state-publisher-system" name="gz::sim::systems::JointStatePublisher">
        <topic>joint_states</topic>
        <joint_name>right_wheel_joint</joint_name>
        <joint_name>left_wheel_joint</joint_name>
      </plugin>

      <!-- <plugin filename="gz-sim-pose-publisher-system" name="gz::sim::systems::PosePublisher"> -->
      <!--   <!-\- <publish_model_pose>true</publish_model_pose> -\-> -->
      <!--   <publish_topic>base_pose_ground_truth</publish_topic> -->
      <!--   <use_pose_vector_msg>true</use_pose_vector_msg> -->
      <!--   <static_publisher>false</static_publisher> -->
      <!-- </plugin> -->
    </gazebo>
    <!-- <ros2_control name="GazeboSimSystem" type="system"> -->
    <!--   <hardware> -->
    <!--     <plugin>gz_ros2_control/GazeboSimSystem</plugin> -->
    <!--   </hardware> -->
    <!--   <joint name="left_wheel_joint"> -->
    <!--     <command_interface name="velocity"> -->
    <!--       <param name="min">-1</param> -->
    <!--       <param name="max">1</param> -->
    <!--     </command_interface> -->
    <!--     <state_interface name="position"/> -->
    <!--     <state_interface name="velocity"/> -->
    <!--   </joint> -->
    <!--   <joint name="right_wheel_joint"> -->
    <!--     <command_interface name="velocity"> -->
    <!--       <param name="min">-1</param> -->
    <!--       <param name="max">1</param> -->
    <!--     </command_interface> -->
    <!--     <state_interface name="position"/> -->
    <!--     <state_interface name="velocity"/> -->
    <!--   </joint> -->
    <!-- </ros2_control> -->
    
    <!-- <gazebo> -->
    <!--   <plugin filename="gz_ros2_control-system" name="gz_ros2_control::GazeboSimROS2ControlPlugin"> -->
    <!--     <ros> -->
    <!--       <namespace>$(arg namespace)</namespace> -->
    <!--     </ros>  -->
    <!--     <parameters>$(find house_simul)/config/diff_drive_controller.yaml</parameters> -->
    <!--   </plugin> -->
    <!-- </gazebo> -->
  
    <gazebo reference="laser_link">
      <sensor name="laser" type="gpu_lidar">
         <pose> 0 0 0 0 0 0 </pose>
         <always_on>true</always_on>
         <visualize>true</visualize>
         <update_rate>10</update_rate>
         <topic>scan</topic>
         <gz_frame_id>laser_link</gz_frame_id>
         <lidar>
           <scan>
             <horizontal>
               <samples>480</samples>
               <min_angle>-2.0944</min_angle>
               <max_angle>2.0944</max_angle>
             </horizontal>
           </scan>
           <range>
             <min>0.1</min>
             <max>10.0</max>
           </range>
           <noise>
             <type>gaussian</type>
             <mean>0.0</mean>
             <stddev>0.02</stddev>
           </noise>
         </lidar>
      </sensor>
    </gazebo>
    
</robot>
